Workbook

Sheet Guide
A1: Topic | B1: Explanation
A2: Title | B2: Contoso Minerals Group | Pelatihan keuangan
A3: Status | B3: MODEL PELATIHAN SEDANG DITINJAU. ANGKA BELUM DISETUJUI.
A4: Scope | B4: Keuangan manajemen Juni sampai Desember 2026 dalam USD. Juni dan Juli ditutup. Agustus masih prakiraan sebelum pembaruan; September sampai Desember tetap berbasis penggerak.
A5: Skills | B5: check-model | model-update | datapack-builder
A6: Workflow | B6: 1 Tinjau aturan dan perbaiki model dengan check-model. 2 Terapkan hanya kejadian Agustus yang disetujui dari 11 dengan model-update. 3 Susun paket keuangan manajemen dengan datapack-builder. Tidak diperlukan skill kustom, Accounting, atau Visualization.
A7: Sites | B7: S01 Lembah Utara dan S02 Bukit Timur: tambang emas beroperasi. S03 Proyek Sentral: pengembangan tembaga-emas. S03 memiliki belanja modal, tetapi tidak memproduksi atau menjual emas.
A8: Owners | B8: Peran fiktif: Arman Pradipta, CFO; Maya Hartono, pengendali keuangan; Dimas Wicaksono, operasi; Nadia Kusuma, perbendaharaan.
A9: Boundaries | B9: Tidak ada klaim pelaporan wajib, pajak, kovenan, atau audit. Surplus operasi = pendapatan faktur dikurangi biaya operasi, sebelum penyusutan, biaya pendanaan, pajak dan biaya bank. Ini bukan EBITDA atau laba bersih.
A10: Independence | B10: Buku besar pengendali yang disetujui disusun dari cetak biru transaksi sebelum impor ditambah tiga penyesuaian pengendali. Secara desain sintetis, sumber ini terpisah dari impor berulang atau belum terselesaikan, bukan audit eksternal.
A11: Stock and sales | B11: Emas batangan awal + produksi - emas dikirim = emas batangan akhir. Pendapatan faktur mengikuti pengiriman yang diterima dan diuji kadarnya. Produksi tidak langsung menjadi pendapatan. Tanggal kirim, faktur dan penyelesaian kas dipisahkan.
A12: Currencies | B12: Nilai sumber USD, IDR dan AUD memakai USD per unit mata uang sesuai periode. Sen USD historis pengendali bersifat otoritatif; nilai lokal disimulasikan hingga enam desimal. Kurs penyelesaian dan biaya bank dipisahkan dari pendapatan faktur.
... A19: Liquidity planning | B19: Cadangan kas grup Desember internal adalah USD 45 juta, indikator rencana ekspansi fiktif, bukan kovenan. Kas lokasi mendatang yang negatif menunjukkan kebutuhan pendanaan belum dialokasikan, bukan cerukan disetujui. Alokasi pendanaan antarentitas di luar model dan harus diputuskan terpisah. Angka kumulatif sejak Juni bukan YTD fiskal penuh.

Sheet Model_Rules
A1: RuleID | B1: Topic | C1: Rule
A2: R01 | B2: USD | C2: Konversi faktur dan sumber prakiraan memakai periode dan mata uang yang sama. Kalikan USD_per_unit. Jangan konversi USD pengendali historis dua kali.
A3: R02 | B3: Opex | C3: Biaya operasi menjumlahkan sepuluh akun 6100 sampai 6190. Akun 1500 sampai 1590 hanya belanja modal pengembangan dan bukan biaya operasi.
A4: R03 | B4: Gold | C4: Ons terjual harus memenuhi awal + produksi - akhir. S03 tidak memiliki produksi atau penjualan. Gunakan hitungan emas tersertifikasi untuk periode ditutup.
A5: R04 | B5: Production | C5: Prakiraan ons = hari x ton bijih/hari x kadar g/t x fraksi perolehan / 31,1034768. Perolehan disimpan sebagai desimal seperti 0,914, bukan 91,4.
A6: R05 | B6: Cash | C6: Cashflow menggabungkan penyelesaian tertunda asal AKTUAL dengan rasio asal PRAKIRAAN: penerimaan 88% berjalan + 12% bulan prakiraan sebelumnya; pembayaran 82% + 18%. Jangan gunakan rasio bulan sebelumnya pada kewajiban aktual. Pisahkan aplikasi buku, kurs penyelesaian kas dan biaya; hanya sisa positif belum dialokasikan diestimasi bulan berikutnya sesuai Settlement_Bridge.
A7: R06 | B7: Range | C7: Semua baris sumber rilis berada dalam tabel Excel. Jumlah faktur periode ditutup harus mencakup pengiriman disetujui yang dibukukan belakangan. Jangan potong rentang pada baris terakhir lama.
A8: R07 | B8: Horizon | C8: Jumlah manajemen mencakup Juni sampai Desember. Cadangan kas grup Desember USD 45 juta adalah indikator rencana ekspansi internal, bukan kovenan pemberi pinjaman. Kas lokasi prakiraan yang negatif menunjukkan kebutuhan pendanaan sebelum alokasi antarentitas.
A9: R08 | B9: Evidence | C9: Controls memakai sertifikat pengendali independen, hitungan persediaan fisik, snapshot Juli tetap dan aturan rumus eksplisit. Nilai harapan tidak boleh tertaut ke keluaran berpotensi salah yang sedang diuji.

Sheet Assumptions
A1: FXKey | B1: Period | C1: Currency | D1: USD_per_unit | E1: ReleaseStatus | F1: EvidenceRef | J1: Parameter | K1: Value | L1: Unit | M1: Explanation
A2: 2026-06|AUD | B2: 46174 | C2: AUD | D2: 0.665 | E2: APPROVED | F2: fx_rates.csv | J2: OpeningCash_S01 | K2: 6000000 | L2: USD | M2: Asumsi kas awal Juni
A3: 2026-06|IDR | B3: 46174 | C3: IDR | D3: 6.25e-05 | E3: APPROVED | F3: fx_rates.csv | J3: OpeningCash_S02 | K3: 4000000 | L3: USD | M3: Asumsi kas awal Juni
A4: 2026-06|USD | B4: 46174 | C4: USD | D4: 1 | E4: APPROVED | F4: fx_rates.csv | J4: OpeningCash_S03 | K4: 9000000 | L4: USD | M4: Asumsi kas awal Juni
A5: 2026-07|AUD | B5: 46204 | C5: AUD | D5: 0.658 | E5: APPROVED | F5: fx_rates.csv | J5: OpeningGold_S01 | K5: 185 | L5: oz | M5: SYN-BULLION-OPEN
A6: 2026-07|IDR | B6: 46204 | C6: IDR | D6: 6.2e-05 | E6: APPROVED | F6: fx_rates.csv | J6: OpeningGold_S02 | K6: 115 | L6: oz | M6: SYN-BULLION-OPEN
A7: 2026-07|USD | B7: 46204 | C7: USD | D7: 1 | E7: APPROVED | F7: fx_rates.csv | J7: OpeningGold_S03 | K7: 0 | L7: oz | M7: SYN-BULLION-OPEN
A8: 2026-08|AUD | B8: 46235 | C8: AUD | D8: 0.65 | E8: APPROVED | F8: fx_rates.csv | J8: CurrentCollectionShare | K8: 0.88 | L8: fraction | M8: SYN-CASH-PROFILE
A9: 2026-08|IDR | B9: 46235 | C9: IDR | D9: 6.15e-05 | E9: APPROVED | F9: fx_rates.csv | J9: CurrentPaymentShare | K9: 0.82 | L9: fraction | M9: SYN-CASH-PROFILE
A10: 2026-08|USD | B10: 46235 | C10: USD | D10: 1 | E10: APPROVED | F10: fx_rates.csv | J10: DecemberCashThreshold | K10: 45000000 | L10: USD | M10: Internal training decision flag
A11: 2026-09|AUD | B11: 46266 | C11: AUD | D11: 0.651 | E11: FORECAST | F11: SYN-FX-PLAN-v1 | J11: OpeningReceivables | K11: 0 | L11: USD | M11: June-start scope; no legacy invoices
A12: 2026-09|IDR | B12: 46266 | C12: IDR | D12: 6.13e-05 | E12: FORECAST | F12: SYN-FX-PLAN-v1
A13: 2026-09|USD | B13: 46266 | C13: USD | D13: 1 | E13: FORECAST | F13: SYN-FX-PLAN-v1
A14: 2026-10|AUD | B14: 46296 | C14: AUD | D14: 0.655 | E14: FORECAST | F14: SYN-FX-PLAN-v1
A15: 2026-10|IDR | B15: 46296 | C15: IDR | D15: 6.11e-05 | E15: FORECAST | F15: SYN-FX-PLAN-v1
A16: 2026-10|USD | B16: 46296 | C16: USD | D16: 1 | E16: FORECAST | F16: SYN-FX-PLAN-v1
A17: 2026-11|AUD | B17: 46327 | C17: AUD | D17: 0.662 | E17: FORECAST | F17: SYN-FX-PLAN-v1
A18: 2026-11|IDR | B18: 46327 | C18: IDR | D18: 6.1e-05 | E18: FORECAST | F18: SYN-FX-PLAN-v1
A19: 2026-11|USD | B19: 46327 | C19: USD | D19: 1 | E19: FORECAST | F19: SYN-FX-PLAN-v1
A20: 2026-12|AUD | B20: 46357 | C20: AUD | D20: 0.659 | E20: FORECAST | F20: SYN-FX-PLAN-v1
A21: 2026-12|IDR | B21: 46357 | C21: IDR | D21: 6.12e-05 | E21: FORECAST | F21: SYN-FX-PLAN-v1
A22: 2026-12|USD | B22: 46357 | C22: USD | D22: 1 | E22: FORECAST | F22: SYN-FX-PLAN-v1

Sheet Period_Status
A1: Period | B1: Status | C1: ReleaseRef | D1: CloseDate | E1: Owner
A2: 46174 | B2: ActualClosed | C2: FIN-REL-2026-06 | D2: 46206 | E2: Maya Hartono
A3: 46204 | B3: ActualClosed | C3: FIN-REL-2026-07 | D3: 46237 | E3: Maya Hartono
A4: 46235 | B4: Forecast | C4: PLAN-v1 | E4: Maya Hartono
A5: 46266 | B5: Forecast | C5: PLAN-v1 | E5: Maya Hartono
A6: 46296 | B6: Forecast | C6: PLAN-v1 | E6: Maya Hartono
A7: 46327 | B7: Forecast | C7: PLAN-v1 | E7: Maya Hartono
A8: 46357 | B8: Forecast | C8: PLAN-v1 | E8: Maya Hartono

Sheet Settlement_Schedule
A1: ApplicationID | B1: Site | C1: SettlementDate | D1: Period | E1: EventType | F1: OriginID | G1: OriginPeriod | H1: ReleaseStatus | I1: Currency | J1: AppliedLocal | K1: SettlementFX | L1: CashUSD | M1: AppliedBookUSD | N1: FeeUSD | O1: PendingActualOrigin | P1: SourceRef
A2: REC-SALE-S01-2026-06-01-1 | B2: S01 | C2: 46191 | D2: 46174 | E2: Collection | F2: SALE-S01-2026-06-01 | G2: 46174 | H2: APPROVED | I2: USD | J2: 1523204.8 | K2: 1 | L2: 1523204.8 | M2: 1523204.8 | N2: 1218.56 | O2: =IF(AND(OR(H2="APPROVED",H2="SCHEDULED"),COUNTIFS(tblSource[EventID],F2,tblSource[ReleaseStatus],"APPROVED")=1,COUNTIFS(Period_Status!$A$2:$A$8,G2,Period_Status!$B$2:$B$8,"ActualClosed")=1,C2>EOMONTH(Settlement_Bridge!$C$2,0)),1,0) -> 0 | P2: RB-SALE-S01-2026-06-01-1
A3: REC-SALE-S01-2026-06-01-2 | B3: S01 | C3: 46211 | D3: 46204 | E3: Collection | F3: SALE-S01-2026-06-01 | G3: 46174 | H3: APPROVED | I3: USD | J3: 268800.84 | K3: 1 | L3: 268800.84 | M3: 268800.84 | N3: 215.04 | O3: =IF(AND(OR(H3="APPROVED",H3="SCHEDULED"),COUNTIFS(tblSource[EventID],F3,tblSource[ReleaseStatus],"APPROVED")=1,COUNTIFS(Period_Status!$A$2:$A$8,G3,Period_Status!$B$2:$B$8,"ActualClosed")=1,C3>EOMONTH(Settlement_Bridge!$C$2,0)),1,0) -> 0 | P3: RB-SALE-S01-2026-06-01-2
A4: REC-SALE-S01-2026-06-02-1 | B4: S01 | C4: 46198 | D4: 46174 | E4: Collection | F4: SALE-S01-2026-06-02 | G4: 46174 | H4: APPROVED | I4: AUD | J4: 2209365 | K4: 0.665 | L4: 1469227.7 | M4: 1469227.7 | N4: 1175.38 | O4: =IF(AND(OR(H4="APPROVED",H4="SCHEDULED"),COUNTIFS(tblSource[EventID],F4,tblSource[ReleaseStatus],"APPROVED")=1,COUNTIFS(Period_Status!$A$2:$A$8,G4,Period_Status!$B$2:$B$8,"ActualClosed")=1,C4>EOMONTH(Settlement_Bridge!$C$2,0)),1,0) -> 0 | P4: RB-SALE-S01-2026-06-02-1
A5: REC-SALE-S01-2026-06-02-2 | B5: S01 | C5: 46218 | D5: 46204 | E5: Collection | F5: SALE-S01-2026-06-02 | G5: 46174 | H5: APPROVED | I5: AUD | J5: 389887.94 | K5: 0.658 | L5: 256546.27 | M5: 259275.48 | N5: 205.24 | O5: =IF(AND(OR(H5="APPROVED",H5="SCHEDULED"),COUNTIFS(tblSource[EventID],F5,tblSource[ReleaseStatus],"APPROVED")=1,COUNTIFS(Period_Status!$A$2:$A$8,G5,Period_Status!$B$2:$B$8,"ActualClosed")=1,C5>EOMONTH(Settlement_Bridge!$C$2,0)),1,0) -> 0 | P5: RB-SALE-S01-2026-06-02-2
A6: REC-SALE-S01-2026-06-03-1 | B6: S01 | C6: 46205 | D6: 46204 | E6: Collection | F6: SALE-S01-2026-06-03 | G6: 46174 | H6: APPROVED | I6: USD | J6: 1436325.2 | K6: 1 | L6: 1436325.1 | M6: 1436325.2 | N6: 1149.06 | O6: =IF(AND(OR(H6="APPROVED",H6="SCHEDULED"),COUNTIFS(tblSource[EventID],F6,tblSource[ReleaseStatus],"APPROVED")=1,COUNTIFS(Period_Status!$A$2:$A$8,G6,Period_Status!$B$2:$B$8,"ActualClosed")=1,C6>EOMONTH(Settlement_Bridge!$C$2,0)),1,0) -> 0 | P6: RB-SALE-S01-2026-06-03-1
A7: REC-SALE-S01-2026-06-03-2 | B7: S01 | C7: 46225 | D7: 46204 | E7: Collection | F7: SALE-S01-2026-06-03 | G7: 46174 | H7: APPROVED | I7: USD | J7: 253469.14 | K7: 1 | L7: 253469.14 | M7: 253469.14 | N7: 202.78 | O7: =IF(AND(OR(H7="APPROVED",H7="SCHEDULED"),COUNTIFS(tblSource[EventID],F7,tblSource[ReleaseStatus],"APPROVED")=1,COUNTIFS(Period_Status!$A$2:$A$8,G7,Period_Status!$B$2:$B$8,"ActualClosed")=1,C7>EOMONTH(Settlement_Bridge!$C$2,0)),1,0) -> 0 | P7: RB-SALE-S01-2026-06-03-2
A8: REC-SALE-S01-2026-06-04-1 | B8: S01 | C8: 46218 | D8: 46204 | E8: Collection | F8: SALE-S01-2026-06-04 | G8: 46174 | H8: APPROVED | I8: AUD | J8: 2752054.9 | K8: 0.658 | L8: 1810852.1 | M8: 1830116.5 | N8: 1448.68 | O8: =IF(AND(OR(H8="APPROVED",H8="SCHEDULED"),COUNTIFS(tblSource[EventID],F8,tblSource[ReleaseStatus],"APPROVED")=1,COUNTIFS(Period_Status!$A$2:$A$8,G8,Period_Status!$B$2:$B$8,"ActualClosed")=1,C8>EOMONTH(Settlement_Bridge!$C$2,0)),1,0) -> 0 | P8: RB-SALE-S01-2026-06-04-1
A9: REC-SALE-S01-2026-06-04-2 | B9: S01 | C9: 46238 | D9: 46235 | E9: Collection | F9: SALE-S01-2026-06-04 | G9: 46174 | H9: APPROVED | I9: AUD | J9: 485656.75 | K9: 0.65 | L9: 315676.89 | M9: 322961.74 | N9: 252.54 | O9: =IF(AND(OR(H9="APPROVED",H9="SCHEDULED"),COUNTIFS(tblSource[EventID],F9,tblSource[ReleaseStatus],"APPROVED")=1,COUNTIFS(Period_Status!$A$2:$A$8,G9,Period_Status!$B$2:$B$8,"ActualClosed")=1,C9>EOMONTH(Settlement_Bridge!$C$2,0)),1,0) -> 1 | P9: RB-SALE-S01-2026-06-04-2
A10: REC-SALE-S01-2026-07-01-1 | B10: S01 | C10: 46221 | D10: 46204 | E10: Collection | F10: SALE-S01-2026-07-01 | G10: 46204 | H10: APPROVED | I10: USD | J10: 1508251.4 | K10: 1 | L10: 1508251.4 | M10: 1508251.4 | N10: 1206.6 | O10: =IF(AND(OR(H10="APPROVED",H10="SCHEDULED"),COUNTIFS(tblSource[EventID],F10,tblSource[ReleaseStatus],"APPROVED")=1,COUNTIFS(Period_Status!$A$2:$A$8,G10,Period_Status!$B$2:$B$8,"ActualClosed")=1,C10>EOMONTH(Settlement_Bridge!$C$2,0)),1,0) -> 0 | P10: RB-SALE-S01-2026-07-01-1
A11: REC-SALE-S01-2026-07-01-2 | B11: S01 | C11: 46241 | D11: 46235 | E11: Collection | F11: SALE-S01-2026-07-01 | G11: 46204 | H11: APPROVED | I11: USD | J11: 266162.01 | K11: 1 | L11: 266162.01 | M11: 266162.01 | N11: 212.93 | O11: =IF(AND(OR(H11="APPROVED",H11="SCHEDULED"),COUNTIFS(tblSource[EventID],F11,tblSource[ReleaseStatus],"APPROVED")=1,COUNTIFS(Period_Status!$A$2:$A$8,G11,Period_Status!$B$2:$B$8,"ActualClosed")=1,C11>EOMONTH(Settlement_Bridge!$C$2,0)),1,0) -> 1 | P11: RB-SALE-S01-2026-07-01-2
A12: REC-SALE-S01-2026-07-02-1 | B12: S01 | C12: 46228 | D12: 46204 | E12: Collection | F12: SALE-S01-2026-07-02 | G12: 46204 | H12: APPROVED | I12: AUD | J12: 2270261.9 | K12: 0.658 | L12: 1493832.3 | M12: 1493832.4 | N12: 1195.07 | O12: =IF(AND(OR(H12="APPROVED",H12="SCHEDULED"),COUNTIFS(tblSource[EventID],F12,tblSource[ReleaseStatus],"APPROVED")=1,COUNTIFS(Period_Status!$A$2:$A$8,G12,Period_Status!$B$2:$B$8,"ActualClosed")=1,C12>EOMONTH(Settlement_Bridge!$C$2,0)),1,0) -> 0 | P12: RB-SALE-S01-2026-07-02-1
A13: REC-SALE-S01-2026-07-02-2 | B13: S01 | C13: 46248 | D13: 46235 | E13: Collection | F13: SALE-S01-2026-07-02 | G13: 46204 | H13: APPROVED | I13: AUD | J13: 400634.46 | K13: 0.65 | L13: 260412.4 | M13: 263617.47 | N13: 208.33 | O13: =IF(AND(OR(H13="APPROVED",H13="SCHEDULED"),COUNTIFS(tblSource[EventID],F13,tblSource[ReleaseStatus],"APPROVED")=1,COUNTIFS(Period_Status!$A$2:$A$8,G13,Period_Status!$B$2:$B$8,"ActualClosed")=1,C13>EOMONTH(Settlement_Bridge!$C$2,0)),1,0) -> 1 | P13: RB-SALE-S01-2026-07-02-2
... A4616: PAY-03003-2 | B4616: S03 | C4616: 46304 | D4616: 46296 | E4616: VendorSettlement | F4616: CTRL-ADJ-3 | G4616: 46235 | H4616: SCHEDULED | I4616: USD | J4616: 4950 | K4616: 1 | L4616: 4950 | M4616: 4950 | N4616: 2.72 | O4616: =IF(AND(OR(H4616="APPROVED",H4616="SCHEDULED"),COUNTIFS(tblSource[EventID],F4616,tblSource[ReleaseStatus],"APPROVED")=1,COUNTIFS(Period_Status!$A$2:$A$8,G4616,Period_Status!$B$2:$B$8,"ActualClosed")=1,C4616>EOMONTH(Settlement_Bridge!$C$2,0)),1,0) -> 0 | P4616: TR-LINE-03003-2

Sheet Settlement_Bridge
A1: Site | B1: SiteName | C1: ActualCutoffPeriod | D1: OutstandingARBookUSD | E1: DatedARBookUSD | F1: UnallocatedARBookUSD | G1: OutstandingAPBookUSD | H1: DatedAPBookUSD | I1: UnallocatedAPBookUSD | J1: AllocationStatus
A2: S01 | B2: Lembah Utara | C2: =LOOKUP(2,1/(Period_Status!$B$2:$B$8="ActualClosed"),Period_Status!$A$2:$A$8) -> 46204 | D2: =SUMIFS(tblSource[AmountUSD],tblSource[Site],A2,tblSource[EventType],"GoldSale",tblSource[ReleaseStatus],"APPROVED",tblSource[Period],"<="&C2)-SUMIFS(tblSource[AppliedUSD],tblSource[Site],A2,tblSource[EventType],"Collection",tblSource[ReleaseStatus],"APPROVED",tblSource[Period],"<="&C2) -> 4933246.4 | E2: =SUMIFS(tblSettlementSchedule[AppliedBookUSD],tblSettlementSchedule[Site],A2,tblSettlementSchedule[EventType],"Collection",tblSettlementSchedule[PendingActualOrigin],1) -> 4933246.4 | F2: =ROUND(D2-E2,2) -> 0 | G2: =SUMIFS(tblSource[AmountUSD],tblSource[Site],A2,tblSource[EventType],"Ledger",tblSource[ReleaseStatus],"APPROVED",tblSource[Period],"<="&C2)-SUMIFS(tblSource[AppliedUSD],tblSource[Site],A2,tblSource[EventType],"VendorSettlement",tblSource[ReleaseStatus],"APPROVED",tblSource[Period],"<="&C2) -> 2080009.8 | H2: =SUMIFS(tblSettlementSchedule[AppliedBookUSD],tblSettlementSchedule[Site],A2,tblSettlementSchedule[EventType],"VendorSettlement",tblSettlementSchedule[PendingActualOrigin],1) -> 2080009.8 | I2: =ROUND(G2-H2,2) -> 0 | J2: =IF(OR(F2<-0.02,I2<-0.02),"REVIEW: overallocated",IF(MAX(F2,I2)>0.02,"ESTIMATE: residual next month","FULLY DATED")) -> FULLY DATED
A3: S02 | B3: Bukit Timur | C3: =LOOKUP(2,1/(Period_Status!$B$2:$B$8="ActualClosed"),Period_Status!$A$2:$A$8) -> 46204 | D3: =SUMIFS(tblSource[AmountUSD],tblSource[Site],A3,tblSource[EventType],"GoldSale",tblSource[ReleaseStatus],"APPROVED",tblSource[Period],"<="&C3)-SUMIFS(tblSource[AppliedUSD],tblSource[Site],A3,tblSource[EventType],"Collection",tblSource[ReleaseStatus],"APPROVED",tblSource[Period],"<="&C3) -> 3028019.2 | E3: =SUMIFS(tblSettlementSchedule[AppliedBookUSD],tblSettlementSchedule[Site],A3,tblSettlementSchedule[EventType],"Collection",tblSettlementSchedule[PendingActualOrigin],1) -> 3028019.2 | F3: =ROUND(D3-E3,2) -> 0 | G3: =SUMIFS(tblSource[AmountUSD],tblSource[Site],A3,tblSource[EventType],"Ledger",tblSource[ReleaseStatus],"APPROVED",tblSource[Period],"<="&C3)-SUMIFS(tblSource[AppliedUSD],tblSource[Site],A3,tblSource[EventType],"VendorSettlement",tblSource[ReleaseStatus],"APPROVED",tblSource[Period],"<="&C3) -> 2076081.4 | H3: =SUMIFS(tblSettlementSchedule[AppliedBookUSD],tblSettlementSchedule[Site],A3,tblSettlementSchedule[EventType],"VendorSettlement",tblSettlementSchedule[PendingActualOrigin],1) -> 2076081.4 | I3: =ROUND(G3-H3,2) -> 0 | J3: =IF(OR(F3<-0.02,I3<-0.02),"REVIEW: overallocated",IF(MAX(F3,I3)>0.02,"ESTIMATE: residual next month","FULLY DATED")) -> FULLY DATED
A4: S03 | B4: Proyek Sentral | C4: =LOOKUP(2,1/(Period_Status!$B$2:$B$8="ActualClosed"),Period_Status!$A$2:$A$8) -> 46204 | D4: =SUMIFS(tblSource[AmountUSD],tblSource[Site],A4,tblSource[EventType],"GoldSale",tblSource[ReleaseStatus],"APPROVED",tblSource[Period],"<="&C4)-SUMIFS(tblSource[AppliedUSD],tblSource[Site],A4,tblSource[EventType],"Collection",tblSource[ReleaseStatus],"APPROVED",tblSource[Period],"<="&C4) -> 0 | E4: =SUMIFS(tblSettlementSchedule[AppliedBookUSD],tblSettlementSchedule[Site],A4,tblSettlementSchedule[EventType],"Collection",tblSettlementSchedule[PendingActualOrigin],1) -> 0 | F4: =ROUND(D4-E4,2) -> 0 | G4: =SUMIFS(tblSource[AmountUSD],tblSource[Site],A4,tblSource[EventType],"Ledger",tblSource[ReleaseStatus],"APPROVED",tblSource[Period],"<="&C4)-SUMIFS(tblSource[AppliedUSD],tblSource[Site],A4,tblSource[EventType],"VendorSettlement",tblSource[ReleaseStatus],"APPROVED",tblSource[Period],"<="&C4) -> 3713937.9 | H4: =SUMIFS(tblSettlementSchedule[AppliedBookUSD],tblSettlementSchedule[Site],A4,tblSettlementSchedule[EventType],"VendorSettlement",tblSettlementSchedule[PendingActualOrigin],1) -> 3713937.9 | I4: =ROUND(G4-H4,2) -> 0 | J4: =IF(OR(F4<-0.02,I4<-0.02),"REVIEW: overallocated",IF(MAX(F4,I4)>0.02,"ESTIMATE: residual next month","FULLY DATED")) -> FULLY DATED
A7: Kebijakan transisi | B7: Aplikasi APPROVED/SCHEDULED bertanggal hanya untuk kewajiban sumber yang sudah ditutup aktual. Baris terjadwal tidak menjadi kejadian aktual. Hanya sisa positif belum dialokasikan diestimasi pada bulan prakiraan pertama pada nilai buku USD, FX 1, biaya penerimaan 0,08% / pembayaran 0,055%. Sisa negatif ditandai REVIEW, tidak dialokasikan diam-diam. Rasio hanya untuk bisnis asal prakiraan, bukan kewajiban aktual.

Sheet Budget
A1: Key | B1: Site | C1: Period | D1: ProductionOz | E1: SalesOz | F1: RevenueUSD | G1: OpexUSD | H1: CapexUSD | I1: OperatingSurplusUSD | J1: CollectionsUSD | K1: VendorPaymentsUSD | L1: BankFeesUSD | M1: NetCashMovementUSD | N1: 6100 | O1: 6110 | P1: 6120 | Q1: 6130 | R1: 6140 | S1: 6150 | T1: 6160 | U1: 6170 | V1: 6180 | W1: 6190
A2: S01|2026-06 | B2: S01 | C2: 46174 | D2: 2664.7439 | E2: 2629.7439 | F2: 7613108.6 | G2: 2506507.7 | H2: 0 | I2: 5106600.8 | J2: 6699535.5 | K2: 2055336.3 | L2: 6490.06 | M2: 4637709.2 | N2: 239400 | O2: 260000 | P2: 227556 | Q2: 267461.04 | R2: 258750 | S2: 253200 | T2: 255622.5 | U2: 261345 | V2: 234050.4 | W2: 249122.79
A3: S01|2026-07 | B3: S01 | C3: 46204 | D3: 2753.5687 | E3: 2688.5687 | F3: 7858686.3 | G3: 2487803 | H3: 0 | I3: 5370883.2 | J3: 7829217 | K3: 2491169.9 | L3: 7633.52 | M3: 5330413.5 | N3: 242550 | O3: 230000 | P3: 225720 | Q3: 249477.84 | R3: 218880 | S3: 261200 | T3: 268642.5 | U3: 249480 | V3: 260822.07 | W3: 281030.64
A4: S01|2026-08 | B4: S01 | C4: 46235 | D4: 2753.5687 | E4: 2673.5687 | F4: 7889701.2 | G4: 2482096.3 | H4: 0 | I4: 5407604.9 | J4: 7885979.4 | K4: 2483123.5 | L4: 7674.5 | M4: 5395181.4 | N4: 226800 | O4: 266000 | P4: 261000 | Q4: 254014.74 | R4: 265980 | S4: 257600 | T4: 211680 | U4: 253260 | V4: 244861.74 | W4: 240899.8
A5: S01|2026-09 | B5: S01 | C5: 46266 | D5: 2718.0388 | E5: 2703.0388 | F5: 8052352.5 | G5: 2562437.1 | H5: 0 | I5: 5489915.4 | J5: 8032834.4 | K5: 2547975.8 | L5: 7827.65 | M5: 5477030.9 | N5: 249826.5 | O5: 236900 | P5: 232491.6 | Q5: 256962.18 | R5: 225446.4 | S5: 269036 | T5: 276701.78 | U5: 256964.4 | V5: 268646.73 | W5: 289461.56
A6: S01|2026-10 | B6: S01 | C6: 46296 | D6: 2863.7114 | E6: 2838.7114 | F6: 8536005.3 | G6: 2612193.2 | H6: 0 | I6: 5923812.1 | J6: 8477967 | K6: 2603237.1 | L6: 8214.15 | M6: 5866515.7 | N6: 254677.5 | O6: 241500 | P6: 237006 | Q6: 261951.73 | R6: 229824 | S6: 274260 | T6: 282074.63 | U6: 261954 | V6: 273863.17 | W6: 295082.17
A7: S01|2026-11 | B7: S01 | C7: 46327 | D7: 2691.3913 | E7: 2651.3913 | F7: 8046972.7 | G7: 2736583.4 | H7: 0 | I7: 5310389.4 | J7: 8105656.6 | K7: 2714193.1 | L7: 7977.33 | M7: 5383486.2 | N7: 266805 | O7: 253000 | P7: 248292 | Q7: 274425.62 | R7: 240768 | S7: 287320 | T7: 295506.75 | U7: 274428 | V7: 286904.28 | W7: 309133.7
A8: S01|2026-12 | B8: S01 | C8: 46357 | D8: 2918.7828 | E8: 2938.7828 | F8: 9001491.8 | G8: 2661949.3 | H8: 0 | I8: 6339542.5 | J8: 8886949.5 | K8: 2675383.4 | L8: 8581.02 | M8: 6202985.1 | N8: 259528.5 | O8: 246100 | P8: 241520.4 | Q8: 266941.29 | R8: 234201.6 | S8: 279484 | T8: 287447.48 | U8: 266943.6 | V8: 279079.61 | W8: 300702.78
A9: S02|2026-06 | B9: S02 | C9: 46174 | D9: 1652.5741 | E9: 1607.5741 | F9: 4653927 | G9: 2480964.4 | H9: 0 | I9: 2172962.6 | J9: 4095455.8 | K9: 2034390.8 | L9: 4395.28 | M9: 2056669.6 | N9: 264600 | O9: 275000 | P9: 225009 | Q9: 249369.12 | R9: 226260 | S9: 223630 | T9: 237545 | U9: 257985 | V9: 245426.94 | W9: 276139.38
A10: S02|2026-07 | B10: S02 | C10: 46204 | D10: 1707.6599 | E10: 1662.6599 | F10: 4859954.9 | G10: 2493381.9 | H10: 0 | I10: 2366572.9 | J10: 4835231.5 | K10: 2491146.8 | L10: 5238.32 | M10: 2338846.4 | N10: 239400 | O10: 234000 | P10: 251028 | Q10: 275676 | R10: 242550 | S10: 273020 | T10: 266656.25 | U10: 234360 | V10: 228241.8 | W10: 248449.89
A11: S02|2026-08 | B11: S02 | C11: 46235 | D11: 1707.6599 | E11: 1652.6599 | F11: 4876999.4 | G11: 2481315.8 | H11: 0 | I11: 2395683.6 | J11: 4874954 | K11: 2483487.7 | L11: 5265.88 | M11: 2386200.4 | N11: 223500 | O11: 231000 | P11: 228492 | Q11: 225834.24 | R11: 264240 | S11: 270180 | T11: 235476.5 | U11: 280000 | V11: 271060.02 | W11: 251533.04
A12: S02|2026-09 | B12: S02 | C12: 46266 | D12: 1685.6256 | E12: 1675.6256 | F12: 4991688.6 | G12: 2568183.4 | H12: 0 | I12: 2423505.2 | J12: 4977925.9 | K12: 2552547.2 | L12: 5386.24 | M12: 2419992.4 | N12: 246582 | O12: 241020 | P12: 258558.84 | Q12: 283946.28 | R12: 249826.5 | S12: 281210.6 | T12: 274655.94 | U12: 241390.8 | V12: 235089.05 | W12: 255903.39
A13: S02|2026-10 | B13: S02 | C13: 46296 | D13: 1775.9663 | E13: 1755.9663 | F13: 5280190.6 | G13: 2618051 | H13: 0 | I13: 2662139.6 | J13: 5245570.4 | K13: 2609074.9 | L13: 5631.45 | M13: 2630864.1 | N13: 251370 | O13: 245700 | P13: 263579.4 | Q13: 289459.8 | R13: 254677.5 | S13: 286671 | T13: 279989.06 | U13: 246078 | V13: 239653.89 | W13: 260872.38
... A22: S03|2026-12 | B22: S03 | C22: 46357 | D22: 0 | E22: 0 | F22: 0 | G22: 0 | H22: 4658630.8 | I22: 0 | J22: 0 | K22: 4466758.4 | L22: 2456.72 | M22: -4469215.1 | N22: 0 | O22: 0 | P22: 0 | Q22: 0 | R22: 0 | S22: 0 | T22: 0 | U22: 0 | V22: 0 | W22: 0

Sheet Actuals_to_July
A1: Key | B1: Site | C1: Period | D1: ProductionOz | E1: SalesOz | F1: RevenueUSD | G1: OpexUSD | H1: CapexUSD | I1: CollectionsUSD | J1: VendorPaymentsUSD | K1: BankFeesUSD | L1: Status
A2: S01|2026-06 | B2: S01 | C2: 46174 | D2: 2566.153 | E2: 2531.153 | F2: 7363381.4 | G2: 2490344.5 | H2: 0 | I2: 2992432.5 | J2: 502261.29 | K2: 2703.95 | L2: FIXED_CONTROLLER_SNAPSHOT
A3: S01|2026-07 | B3: S01 | C3: 46204 | D3: 2652.8931 | E3: 2587.8931 | F3: 7612368.4 | G3: 2468255.1 | H3: 0 | I3: 7028077.3 | J3: 2365180.8 | K3: 7035.79 | L3: FIXED_CONTROLLER_SNAPSHOT
A4: S02|2026-06 | B4: S02 | C4: 46174 | D4: 1570.0351 | E4: 1525.0351 | F4: 4453289.6 | G4: 2461091.5 | H4: 0 | I4: 1799168.6 | J4: 496568.89 | K4: 1749.75 | L4: FIXED_CONTROLLER_SNAPSHOT
A5: S02|2026-07 | B5: S02 | C5: 46204 | D5: 1617.1965 | E5: 1572.1965 | F5: 4641948 | G5: 2481002.1 | H5: 0 | I5: 4254932.3 | J5: 2358176.9 | K5: 4817.49 | L5: FIXED_CONTROLLER_SNAPSHOT
A6: S03|2026-06 | B6: S03 | C6: 46174 | D6: 0 | E6: 0 | F6: 0 | G6: 0 | H6: 3958141.6 | I6: 0 | J6: 817042.43 | K6: 516.31 | L6: FIXED_CONTROLLER_SNAPSHOT
A7: S03|2026-07 | B7: S03 | C7: 46204 | D7: 0 | E7: 0 | F7: 0 | G7: 0 | H7: 3922798.5 | I7: 0 | J7: 3334748.1 | K7: 1989.68 | L7: FIXED_CONTROLLER_SNAPSHOT

Sheet Forecast_Drivers
A1: Key | B1: Site | C1: Period | D1: Days | E1: OreTonnesPerDay | F1: HeadGrade_gpt | G1: RecoveryPct | H1: ProductionOz | I1: ClosingBullionOz | J1: PriceCurrency | K1: PriceLocalPerOz | L1: OpexFactor | M1: CapexPlanUSD | N1: Notes
A2: S01|2026-06 | B2: S01 | C2: 46174 | D2: 30 | E2: 2200 | F2: 1.38 | G2: 0.914 | H2: =IF(INDEX(Period_Status!$B$2:$B$8,MATCH(C2,Period_Status!$A$2:$A$8,0))="ActualClosed",SUMIFS(tblSource[QuantityOz],tblSource[Site],B2,tblSource[Period],C2,tblSource[EventType],"Production",tblSource[ReleaseStatus],"APPROVED"),D2*E2*F2*G2/31.1034768) -> 2566.153 | I2: 220 | J2: USD | K2: 2920 | L2: 1 | M2: 0 | N2: Asumsi rencana; produksi ditutup memakai sumber harian disetujui
A3: S01|2026-07 | B3: S01 | C3: 46204 | D3: 31 | E3: 2220 | F3: 1.39 | G3: 0.912 | H3: =IF(INDEX(Period_Status!$B$2:$B$8,MATCH(C3,Period_Status!$A$2:$A$8,0))="ActualClosed",SUMIFS(tblSource[QuantityOz],tblSource[Site],B3,tblSource[Period],C3,tblSource[EventType],"Production",tblSource[ReleaseStatus],"APPROVED"),D3*E3*F3*G3/31.1034768) -> 2652.8931 | I3: 285 | J3: USD | K3: 2950 | L3: 1 | M3: 0 | N3: Asumsi rencana; produksi ditutup memakai sumber harian disetujui
A4: S01|2026-08 | B4: S01 | C4: 46235 | D4: 31 | E4: 2320 | F4: 1.4 | G4: 0.916 | H4: =IF(INDEX(Period_Status!$B$2:$B$8,MATCH(C4,Period_Status!$A$2:$A$8,0))="ActualClosed",SUMIFS(tblSource[QuantityOz],tblSource[Site],B4,tblSource[Period],C4,tblSource[EventType],"Production",tblSource[ReleaseStatus],"APPROVED"),D4*E4*F4*G4/31.1034768) -> 2965.27 | I4: 330 | J4: USD | K4: 2980 | L4: 1.06 | M4: 0 | N4: Asumsi rencana; produksi ditutup memakai sumber harian disetujui
A5: S01|2026-09 | B5: S01 | C5: 46266 | D5: 30 | E5: 2360 | F5: 1.405 | G5: 0.918 | H5: =IF(INDEX(Period_Status!$B$2:$B$8,MATCH(C5,Period_Status!$A$2:$A$8,0))="ActualClosed",SUMIFS(tblSource[QuantityOz],tblSource[Site],B5,tblSource[Period],C5,tblSource[EventType],"Production",tblSource[ReleaseStatus],"APPROVED"),D5*E5*F5*G5/31.1034768) -> 2935.914 | I5: 345 | J5: USD | K5: 3010 | L5: 1.04 | M5: 0 | N5: Asumsi rencana; produksi ditutup memakai sumber harian disetujui
A6: S01|2026-10 | B6: S01 | C6: 46296 | D6: 31 | E6: 2380 | F6: 1.41 | G6: 0.921 | H6: =IF(INDEX(Period_Status!$B$2:$B$8,MATCH(C6,Period_Status!$A$2:$A$8,0))="ActualClosed",SUMIFS(tblSource[QuantityOz],tblSource[Site],B6,tblSource[Period],C6,tblSource[EventType],"Production",tblSource[ReleaseStatus],"APPROVED"),D6*E6*F6*G6/31.1034768) -> 3080.4095 | I6: 370 | J6: USD | K6: 3040 | L6: 1.08 | M6: 0 | N6: Asumsi rencana; produksi ditutup memakai sumber harian disetujui
A7: S01|2026-11 | B7: S01 | C7: 46327 | D7: 30 | E7: 2260 | F7: 1.39 | G7: 0.913 | H7: =IF(INDEX(Period_Status!$B$2:$B$8,MATCH(C7,Period_Status!$A$2:$A$8,0))="ActualClosed",SUMIFS(tblSource[QuantityOz],tblSource[Site],B7,tblSource[Period],C7,tblSource[EventType],"Production",tblSource[ReleaseStatus],"APPROVED"),D7*E7*F7*G7/31.1034768) -> 2766.345 | I7: 410 | J7: USD | K7: 3070 | L7: 1.14 | M7: 0 | N7: Asumsi rencana; produksi ditutup memakai sumber harian disetujui
A8: S01|2026-12 | B8: S01 | C8: 46357 | D8: 31 | E8: 2410 | F8: 1.42 | G8: 0.922 | H8: =IF(INDEX(Period_Status!$B$2:$B$8,MATCH(C8,Period_Status!$A$2:$A$8,0))="ActualClosed",SUMIFS(tblSource[QuantityOz],tblSource[Site],B8,tblSource[Period],C8,tblSource[EventType],"Production",tblSource[ReleaseStatus],"APPROVED"),D8*E8*F8*G8/31.1034768) -> 3144.7713 | I8: 390 | J8: USD | K8: 3100 | L8: 1.05 | M8: 0 | N8: Asumsi rencana; produksi ditutup memakai sumber harian disetujui
A9: S02|2026-06 | B9: S02 | C9: 46174 | D9: 30 | E9: 1600 | F9: 1.24 | G9: 0.9 | H9: =IF(INDEX(Period_Status!$B$2:$B$8,MATCH(C9,Period_Status!$A$2:$A$8,0))="ActualClosed",SUMIFS(tblSource[QuantityOz],tblSource[Site],B9,tblSource[Period],C9,tblSource[EventType],"Production",tblSource[ReleaseStatus],"APPROVED"),D9*E9*F9*G9/31.1034768) -> 1570.0351 | I9: 160 | J9: AUD | K9: 4390.9774 | L9: 1 | M9: 0 | N9: Asumsi rencana; produksi ditutup memakai sumber harian disetujui
A10: S02|2026-07 | B10: S02 | C10: 46204 | D10: 31 | E10: 1580 | F10: 1.23 | G10: 0.895 | H10: =IF(INDEX(Period_Status!$B$2:$B$8,MATCH(C10,Period_Status!$A$2:$A$8,0))="ActualClosed",SUMIFS(tblSource[QuantityOz],tblSource[Site],B10,tblSource[Period],C10,tblSource[EventType],"Production",tblSource[ReleaseStatus],"APPROVED"),D10*E10*F10*G10/31.1034768) -> 1617.1965 | I10: 205 | J10: AUD | K10: 4483.2827 | L10: 1 | M10: 0 | N10: Asumsi rencana; produksi ditutup memakai sumber harian disetujui
A11: S02|2026-08 | B11: S02 | C11: 46235 | D11: 31 | E11: 1650 | F11: 1.25 | G11: 0.899 | H11: =IF(INDEX(Period_Status!$B$2:$B$8,MATCH(C11,Period_Status!$A$2:$A$8,0))="ActualClosed",SUMIFS(tblSource[QuantityOz],tblSource[Site],B11,tblSource[Period],C11,tblSource[EventType],"Production",tblSource[ReleaseStatus],"APPROVED"),D11*E11*F11*G11/31.1034768) -> 1848.0189 | I11: 245 | J11: AUD | K11: 4584.6154 | L11: 1.06 | M11: 0 | N11: Asumsi rencana; produksi ditutup memakai sumber harian disetujui
A12: S02|2026-09 | B12: S02 | C12: 46266 | D12: 30 | E12: 1690 | F12: 1.26 | G12: 0.905 | H12: =IF(INDEX(Period_Status!$B$2:$B$8,MATCH(C12,Period_Status!$A$2:$A$8,0))="ActualClosed",SUMIFS(tblSource[QuantityOz],tblSource[Site],B12,tblSource[Period],C12,tblSource[EventType],"Production",tblSource[ReleaseStatus],"APPROVED"),D12*E12*F12*G12/31.1034768) -> 1858.7379 | I12: 255 | J12: AUD | K12: 4623.6559 | L12: 1.04 | M12: 0 | N12: Asumsi rencana; produksi ditutup memakai sumber harian disetujui
A13: S02|2026-10 | B13: S02 | C13: 46296 | D13: 31 | E13: 1710 | F13: 1.27 | G13: 0.908 | H13: =D13*E13*F13*(G13/100)/31.1034768 -> 19.653434 | I13: 275 | J13: AUD | K13: 4641.2214 | L13: 1.08 | M13: 0 | N13: Asumsi rencana; produksi ditutup memakai sumber harian disetujui
A14: S02|2026-11 | B14: S02 | C14: 46327 | D14: 30 | E14: 1580 | F14: 1.24 | G14: 0.896 | H14: =IF(INDEX(Period_Status!$B$2:$B$8,MATCH(C14,Period_Status!$A$2:$A$8,0))="ActualClosed",SUMIFS(tblSource[QuantityOz],tblSource[Site],B14,tblSource[Period],C14,tblSource[EventType],"Production",tblSource[ReleaseStatus],"APPROVED"),D14*E14*F14*G14/31.1034768) -> 1693.1643 | I14: 290 | J14: AUD | K14: 4637.4622 | L14: 1.14 | M14: 0 | N14: Asumsi rencana; produksi ditutup memakai sumber harian disetujui
A15: S02|2026-12 | B15: S02 | C15: 46357 | D15: 31 | E15: 1720 | F15: 1.28 | G15: 0.91 | H15: =IF(INDEX(Period_Status!$B$2:$B$8,MATCH(C15,Period_Status!$A$2:$A$8,0))="ActualClosed",SUMIFS(tblSource[QuantityOz],tblSource[Site],B15,tblSource[Period],C15,tblSource[EventType],"Production",tblSource[ReleaseStatus],"APPROVED"),D15*E15*F15*G15/31.1034768) -> 1996.7908 | I15: 280 | J15: AUD | K15: 4704.0971 | L15: 1.05 | M15: 0 | N15: Asumsi rencana; produksi ditutup memakai sumber harian disetujui
A16: S03|2026-06 | B16: S03 | C16: 46174 | D16: 30 | E16: 0 | F16: 0 | G16: 0 | H16: =IF(INDEX(Period_Status!$B$2:$B$8,MATCH(C16,Period_Status!$A$2:$A$8,0))="ActualClosed",SUMIFS(tblSource[QuantityOz],tblSource[Site],B16,tblSource[Period],C16,tblSource[EventType],"Production",tblSource[ReleaseStatus],"APPROVED"),D16*E16*F16*G16/31.1034768) -> 0 | I16: 0 | J16: USD | K16: 2920 | L16: 1 | M16: 3981370.5 | N16: Asumsi rencana; produksi ditutup memakai sumber harian disetujui
A17: S03|2026-07 | B17: S03 | C17: 46204 | D17: 31 | E17: 0 | F17: 0 | G17: 0 | H17: =IF(INDEX(Period_Status!$B$2:$B$8,MATCH(C17,Period_Status!$A$2:$A$8,0))="ActualClosed",SUMIFS(tblSource[QuantityOz],tblSource[Site],B17,tblSource[Period],C17,tblSource[EventType],"Production",tblSource[ReleaseStatus],"APPROVED"),D17*E17*F17*G17/31.1034768) -> 0 | I17: 0 | J17: USD | K17: 2950 | L17: 1 | M17: 3947992.2 | N17: Asumsi rencana; produksi ditutup memakai sumber harian disetujui
A18: S03|2026-08 | B18: S03 | C18: 46235 | D18: 31 | E18: 0 | F18: 0 | G18: 0 | H18: =IF(INDEX(Period_Status!$B$2:$B$8,MATCH(C18,Period_Status!$A$2:$A$8,0))="ActualClosed",SUMIFS(tblSource[QuantityOz],tblSource[Site],B18,tblSource[Period],C18,tblSource[EventType],"Production",tblSource[ReleaseStatus],"APPROVED"),D18*E18*F18*G18/31.1034768) -> 0 | I18: 0 | J18: USD | K18: 2980 | L18: 1.06 | M18: 4282850.1 | N18: Asumsi rencana; produksi ditutup memakai sumber harian disetujui
A19: S03|2026-09 | B19: S03 | C19: 46266 | D19: 30 | E19: 0 | F19: 0 | G19: 0 | H19: =IF(INDEX(Period_Status!$B$2:$B$8,MATCH(C19,Period_Status!$A$2:$A$8,0))="ActualClosed",SUMIFS(tblSource[QuantityOz],tblSource[Site],B19,tblSource[Period],C19,tblSource[EventType],"Production",tblSource[ReleaseStatus],"APPROVED"),D19*E19*F19*G19/31.1034768) -> 0 | I19: 0 | J19: USD | K19: 3010 | L19: 1.04 | M19: 3865874 | N19: Asumsi rencana; produksi ditutup memakai sumber harian disetujui
A20: S03|2026-10 | B20: S03 | C20: 46296 | D20: 31 | E20: 0 | F20: 0 | G20: 0 | H20: =IF(INDEX(Period_Status!$B$2:$B$8,MATCH(C20,Period_Status!$A$2:$A$8,0))="ActualClosed",SUMIFS(tblSource[QuantityOz],tblSource[Site],B20,tblSource[Period],C20,tblSource[EventType],"Production",tblSource[ReleaseStatus],"APPROVED"),D20*E20*F20*G20/31.1034768) -> 0 | I20: 0 | J20: USD | K20: 3040 | L20: 1.08 | M20: 4770753.8 | N20: Asumsi rencana; produksi ditutup memakai sumber harian disetujui
A21: S03|2026-11 | B21: S03 | C21: 46327 | D21: 30 | E21: 0 | F21: 0 | G21: 0 | H21: =IF(INDEX(Period_Status!$B$2:$B$8,MATCH(C21,Period_Status!$A$2:$A$8,0))="ActualClosed",SUMIFS(tblSource[QuantityOz],tblSource[Site],B21,tblSource[Period],C21,tblSource[EventType],"Production",tblSource[ReleaseStatus],"APPROVED"),D21*E21*F21*G21/31.1034768) -> 0 | I21: 0 | J21: USD | K21: 3070 | L21: 1.14 | M21: 3484892.7 | N21: Asumsi rencana; produksi ditutup memakai sumber harian disetujui
A22: S03|2026-12 | B22: S03 | C22: 46357 | D22: 31 | E22: 0 | F22: 0 | G22: 0 | H22: =IF(INDEX(Period_Status!$B$2:$B$8,MATCH(C22,Period_Status!$A$2:$A$8,0))="ActualClosed",SUMIFS(tblSource[QuantityOz],tblSource[Site],B22,tblSource[Period],C22,tblSource[EventType],"Production",tblSource[ReleaseStatus],"APPROVED"),D22*E22*F22*G22/31.1034768) -> 0 | I22: 0 | J22: USD | K22: 3100 | L22: 1.05 | M22: 5217666.5 | N22: Asumsi rencana; produksi ditutup memakai sumber harian disetujui

Sheet Gold_Stock
A1: Key | B1: Site | C1: Period | D1: OpeningOz | E1: ProductionOz | F1: ShippedOz | G1: ClosingOz | H1: BridgeResidualOz | I1: CountRef
A2: S01|2026-06 | B2: S01 | C2: 46174 | D2: =Assumptions!$K$5 -> 185 | E2: =Forecast_Drivers!H2 -> 2566.153 | F2: =IF(INDEX(Period_Status!$B$2:$B$8,MATCH(C2,Period_Status!$A$2:$A$8,0))="ActualClosed",SUMIFS(tblSource[QuantityOz],tblSource[Site],B2,tblSource[Period],C2,tblSource[EventType],"GoldSale",tblSource[ReleaseStatus],"APPROVED"),MAX(0,D2+E2-G2)) -> 2531.153 | G2: =Forecast_Drivers!I2 -> 220 | H2: =D2+E2-F2-G2 -> 4.5474735e-13 | I2: BULLION-COUNT-S01-2026-06
A3: S01|2026-07 | B3: S01 | C3: 46204 | D3: =G2 -> 220 | E3: =Forecast_Drivers!H3 -> 2652.8931 | F3: =IF(INDEX(Period_Status!$B$2:$B$8,MATCH(C3,Period_Status!$A$2:$A$8,0))="ActualClosed",SUMIFS(tblSource[QuantityOz],tblSource[Site],B3,tblSource[Period],C3,tblSource[EventType],"GoldSale",tblSource[ReleaseStatus],"APPROVED"),MAX(0,D3+E3-G3)) -> 2587.8931 | G3: =Forecast_Drivers!I3 -> 285 | H3: =D3+E3-F3-G3 -> 1.3642421e-12 | I3: BULLION-COUNT-S01-2026-07
A4: S01|2026-08 | B4: S01 | C4: 46235 | D4: =G3 -> 285 | E4: =Forecast_Drivers!H4 -> 2965.27 | F4: =IF(INDEX(Period_Status!$B$2:$B$8,MATCH(C4,Period_Status!$A$2:$A$8,0))="ActualClosed",SUMIFS(tblSource[QuantityOz],tblSource[Site],B4,tblSource[Period],C4,tblSource[EventType],"GoldSale",tblSource[ReleaseStatus],"APPROVED"),MAX(0,D4+E4-G4)) -> 2920.27 | G4: =Forecast_Drivers!I4 -> 330 | H4: =D4+E4-F4-G4 -> 0 | I4: BULLION-COUNT-S01-2026-08
A5: S01|2026-09 | B5: S01 | C5: 46266 | D5: =G4 -> 330 | E5: =Forecast_Drivers!H5 -> 2935.914 | F5: =E5 -> 2935.914 | G5: =Forecast_Drivers!I5 -> 345 | H5: =D5+E5-F5-G5 -> -15 | I5: SYN-BULLION-PLAN
A6: S01|2026-10 | B6: S01 | C6: 46296 | D6: =G5 -> 345 | E6: =Forecast_Drivers!H6 -> 3080.4095 | F6: =IF(INDEX(Period_Status!$B$2:$B$8,MATCH(C6,Period_Status!$A$2:$A$8,0))="ActualClosed",SUMIFS(tblSource[QuantityOz],tblSource[Site],B6,tblSource[Period],C6,tblSource[EventType],"GoldSale",tblSource[ReleaseStatus],"APPROVED"),MAX(0,D6+E6-G6)) -> 3055.4095 | G6: =Forecast_Drivers!I6 -> 370 | H6: =D6+E6-F6-G6 -> 0 | I6: SYN-BULLION-PLAN
A7: S01|2026-11 | B7: S01 | C7: 46327 | D7: =G6 -> 370 | E7: =Forecast_Drivers!H7 -> 2766.345 | F7: =IF(INDEX(Period_Status!$B$2:$B$8,MATCH(C7,Period_Status!$A$2:$A$8,0))="ActualClosed",SUMIFS(tblSource[QuantityOz],tblSource[Site],B7,tblSource[Period],C7,tblSource[EventType],"GoldSale",tblSource[ReleaseStatus],"APPROVED"),MAX(0,D7+E7-G7)) -> 2726.345 | G7: =Forecast_Drivers!I7 -> 410 | H7: =D7+E7-F7-G7 -> 0 | I7: SYN-BULLION-PLAN
A8: S01|2026-12 | B8: S01 | C8: 46357 | D8: =G7 -> 410 | E8: =Forecast_Drivers!H8 -> 3144.7713 | F8: =IF(INDEX(Period_Status!$B$2:$B$8,MATCH(C8,Period_Status!$A$2:$A$8,0))="ActualClosed",SUMIFS(tblSource[QuantityOz],tblSource[Site],B8,tblSource[Period],C8,tblSource[EventType],"GoldSale",tblSource[ReleaseStatus],"APPROVED"),MAX(0,D8+E8-G8)) -> 3164.7713 | G8: =Forecast_Drivers!I8 -> 390 | H8: =D8+E8-F8-G8 -> 0 | I8: SYN-BULLION-PLAN
A9: S02|2026-06 | B9: S02 | C9: 46174 | D9: =Assumptions!$K$6 -> 115 | E9: =Forecast_Drivers!H9 -> 1570.0351 | F9: =IF(INDEX(Period_Status!$B$2:$B$8,MATCH(C9,Period_Status!$A$2:$A$8,0))="ActualClosed",SUMIFS(tblSource[QuantityOz],tblSource[Site],B9,tblSource[Period],C9,tblSource[EventType],"GoldSale",tblSource[ReleaseStatus],"APPROVED"),MAX(0,D9+E9-G9)) -> 1525.0351 | G9: =Forecast_Drivers!I9 -> 160 | H9: =D9+E9-F9-G9 -> 0 | I9: BULLION-COUNT-S02-2026-06
A10: S02|2026-07 | B10: S02 | C10: 46204 | D10: =G9 -> 160 | E10: =Forecast_Drivers!H10 -> 1617.1965 | F10: =IF(INDEX(Period_Status!$B$2:$B$8,MATCH(C10,Period_Status!$A$2:$A$8,0))="ActualClosed",SUMIFS(tblSource[QuantityOz],tblSource[Site],B10,tblSource[Period],C10,tblSource[EventType],"GoldSale",tblSource[ReleaseStatus],"APPROVED"),MAX(0,D10+E10-G10)) -> 1572.1965 | G10: =Forecast_Drivers!I10 -> 205 | H10: =D10+E10-F10-G10 -> 4.5474735e-13 | I10: BULLION-COUNT-S02-2026-07
A11: S02|2026-08 | B11: S02 | C11: 46235 | D11: =G10 -> 205 | E11: =Forecast_Drivers!H11 -> 1848.0189 | F11: =IF(INDEX(Period_Status!$B$2:$B$8,MATCH(C11,Period_Status!$A$2:$A$8,0))="ActualClosed",SUMIFS(tblSource[QuantityOz],tblSource[Site],B11,tblSource[Period],C11,tblSource[EventType],"GoldSale",tblSource[ReleaseStatus],"APPROVED"),MAX(0,D11+E11-G11)) -> 1808.0189 | G11: =Forecast_Drivers!I11 -> 245 | H11: =D11+E11-F11-G11 -> 0 | I11: BULLION-COUNT-S02-2026-08
A12: S02|2026-09 | B12: S02 | C12: 46266 | D12: =G11 -> 245 | E12: =Forecast_Drivers!H12 -> 1858.7379 | F12: =IF(INDEX(Period_Status!$B$2:$B$8,MATCH(C12,Period_Status!$A$2:$A$8,0))="ActualClosed",SUMIFS(tblSource[QuantityOz],tblSource[Site],B12,tblSource[Period],C12,tblSource[EventType],"GoldSale",tblSource[ReleaseStatus],"APPROVED"),MAX(0,D12+E12-G12)) -> 1848.7379 | G12: =Forecast_Drivers!I12 -> 255 | H12: =D12+E12-F12-G12 -> 0 | I12: SYN-BULLION-PLAN
A13: S02|2026-10 | B13: S02 | C13: 46296 | D13: =G12 -> 255 | E13: =Forecast_Drivers!H13 -> 19.653434 | F13: =IF(INDEX(Period_Status!$B$2:$B$8,MATCH(C13,Period_Status!$A$2:$A$8,0))="ActualClosed",SUMIFS(tblSource[QuantityOz],tblSource[Site],B13,tblSource[Period],C13,tblSource[EventType],"GoldSale",tblSource[ReleaseStatus],"APPROVED"),MAX(0,D13+E13-G13)) -> 0 | G13: =Forecast_Drivers!I13 -> 275 | H13: =D13+E13-F13-G13 -> -0.3465664 | I13: SYN-BULLION-PLAN
A14: S02|2026-11 | B14: S02 | C14: 46327 | D14: =G13 -> 275 | E14: =Forecast_Drivers!H14 -> 1693.1643 | F14: =IF(INDEX(Period_Status!$B$2:$B$8,MATCH(C14,Period_Status!$A$2:$A$8,0))="ActualClosed",SUMIFS(tblSource[QuantityOz],tblSource[Site],B14,tblSource[Period],C14,tblSource[EventType],"GoldSale",tblSource[ReleaseStatus],"APPROVED"),MAX(0,D14+E14-G14)) -> 1678.1643 | G14: =Forecast_Drivers!I14 -> 290 | H14: =D14+E14-F14-G14 -> 0 | I14: SYN-BULLION-PLAN
A15: S02|2026-12 | B15: S02 | C15: 46357 | D15: =G14 -> 290 | E15: =Forecast_Drivers!H15 -> 1996.7908 | F15: =IF(INDEX(Period_Status!$B$2:$B$8,MATCH(C15,Period_Status!$A$2:$A$8,0))="ActualClosed",SUMIFS(tblSource[QuantityOz],tblSource[Site],B15,tblSource[Period],C15,tblSource[EventType],"GoldSale",tblSource[ReleaseStatus],"APPROVED"),MAX(0,D15+E15-G15)) -> 2006.7908 | G15: =Forecast_Drivers!I15 -> 280 | H15: =D15+E15-F15-G15 -> 0 | I15: SYN-BULLION-PLAN
A16: S03|2026-06 | B16: S03 | C16: 46174 | D16: =Assumptions!$K$7 -> 0 | E16: =Forecast_Drivers!H16 -> 0 | F16: =IF(INDEX(Period_Status!$B$2:$B$8,MATCH(C16,Period_Status!$A$2:$A$8,0))="ActualClosed",SUMIFS(tblSource[QuantityOz],tblSource[Site],B16,tblSource[Period],C16,tblSource[EventType],"GoldSale",tblSource[ReleaseStatus],"APPROVED"),MAX(0,D16+E16-G16)) -> 0 | G16: =Forecast_Drivers!I16 -> 0 | H16: =D16+E16-F16-G16 -> 0 | I16: BULLION-COUNT-S03-2026-06
A17: S03|2026-07 | B17: S03 | C17: 46204 | D17: =G16 -> 0 | E17: =Forecast_Drivers!H17 -> 0 | F17: =IF(INDEX(Period_Status!$B$2:$B$8,MATCH(C17,Period_Status!$A$2:$A$8,0))="ActualClosed",SUMIFS(tblSource[QuantityOz],tblSource[Site],B17,tblSource[Period],C17,tblSource[EventType],"GoldSale",tblSource[ReleaseStatus],"APPROVED"),MAX(0,D17+E17-G17)) -> 0 | G17: =Forecast_Drivers!I17 -> 0 | H17: =D17+E17-F17-G17 -> 0 | I17: BULLION-COUNT-S03-2026-07
A18: S03|2026-08 | B18: S03 | C18: 46235 | D18: =G17 -> 0 | E18: =Forecast_Drivers!H18 -> 0 | F18: =IF(INDEX(Period_Status!$B$2:$B$8,MATCH(C18,Period_Status!$A$2:$A$8,0))="ActualClosed",SUMIFS(tblSource[QuantityOz],tblSource[Site],B18,tblSource[Period],C18,tblSource[EventType],"GoldSale",tblSource[ReleaseStatus],"APPROVED"),MAX(0,D18+E18-G18)) -> 0 | G18: =Forecast_Drivers!I18 -> 0 | H18: =D18+E18-F18-G18 -> 0 | I18: BULLION-COUNT-S03-2026-08
A19: S03|2026-09 | B19: S03 | C19: 46266 | D19: =G18 -> 0 | E19: =Forecast_Drivers!H19 -> 0 | F19: =IF(INDEX(Period_Status!$B$2:$B$8,MATCH(C19,Period_Status!$A$2:$A$8,0))="ActualClosed",SUMIFS(tblSource[QuantityOz],tblSource[Site],B19,tblSource[Period],C19,tblSource[EventType],"GoldSale",tblSource[ReleaseStatus],"APPROVED"),MAX(0,D19+E19-G19)) -> 0 | G19: =Forecast_Drivers!I19 -> 0 | H19: =D19+E19-F19-G19 -> 0 | I19: SYN-BULLION-PLAN
A20: S03|2026-10 | B20: S03 | C20: 46296 | D20: =G19 -> 0 | E20: =Forecast_Drivers!H20 -> 0 | F20: =IF(INDEX(Period_Status!$B$2:$B$8,MATCH(C20,Period_Status!$A$2:$A$8,0))="ActualClosed",SUMIFS(tblSource[QuantityOz],tblSource[Site],B20,tblSource[Period],C20,tblSource[EventType],"GoldSale",tblSource[ReleaseStatus],"APPROVED"),MAX(0,D20+E20-G20)) -> 0 | G20: =Forecast_Drivers!I20 -> 0 | H20: =D20+E20-F20-G20 -> 0 | I20: SYN-BULLION-PLAN
A21: S03|2026-11 | B21: S03 | C21: 46327 | D21: =G20 -> 0 | E21: =Forecast_Drivers!H21 -> 0 | F21: =IF(INDEX(Period_Status!$B$2:$B$8,MATCH(C21,Period_Status!$A$2:$A$8,0))="ActualClosed",SUMIFS(tblSource[QuantityOz],tblSource[Site],B21,tblSource[Period],C21,tblSource[EventType],"GoldSale",tblSource[ReleaseStatus],"APPROVED"),MAX(0,D21+E21-G21)) -> 0 | G21: =Forecast_Drivers!I21 -> 0 | H21: =D21+E21-F21-G21 -> 0 | I21: SYN-BULLION-PLAN
A22: S03|2026-12 | B22: S03 | C22: 46357 | D22: =G21 -> 0 | E22: =Forecast_Drivers!H22 -> 0 | F22: =IF(INDEX(Period_Status!$B$2:$B$8,MATCH(C22,Period_Status!$A$2:$A$8,0))="ActualClosed",SUMIFS(tblSource[QuantityOz],tblSource[Site],B22,tblSource[Period],C22,tblSource[EventType],"GoldSale",tblSource[ReleaseStatus],"APPROVED"),MAX(0,D22+E22-G22)) -> 0 | G22: =Forecast_Drivers!I22 -> 0 | H22: =D22+E22-F22-G22 -> 0 | I22: SYN-BULLION-PLAN

Sheet Revenue
A1: Key | B1: Site | C1: Period | D1: ShippedOz | E1: PriceBasisCurrency | F1: PricePerOz | G1: USDPerPriceUnit | H1: RevenueUSD | I1: RuleExpectedUSD | J1: ResidualUSD
A2: S01|2026-06 | B2: S01 | C2: 46174 | D2: =Gold_Stock!F2 -> 2531.153 | E2: =IF(INDEX(Period_Status!$B$2:$B$8,MATCH(C2,Period_Status!$A$2:$A$8,0))="ActualClosed","USD reporting",Forecast_Drivers!J2) -> USD reporting | F2: =IF(INDEX(Period_Status!$B$2:$B$8,MATCH(C2,Period_Status!$A$2:$A$8,0))="ActualClosed",IFERROR(SUMIFS(tblSource[AmountUSD],tblSource[Site],B2,tblSource[Period],C2,tblSource[EventType],"GoldSale",tblSource[ReleaseStatus],"APPROVED")/SUMIFS(tblSource[QuantityOz],tblSource[Site],B2,tblSource[Period],C2,tblSource[EventType],"GoldSale",tblSource[ReleaseStatus],"APPROVED"),0),Forecast_Drivers!K2) -> 2909.1017 | G2: =IF(INDEX(Period_Status!$B$2:$B$8,MATCH(C2,Period_Status!$A$2:$A$8,0))="ActualClosed",1,SUMIFS(tblFX[USD_per_unit],tblFX[Period],C2,tblFX[Currency],E2)) -> 1 | H2: =IF(INDEX(Period_Status!$B$2:$B$8,MATCH(C2,Period_Status!$A$2:$A$8,0))="ActualClosed",SUMIFS(tblSource[AmountUSD],tblSource[Site],B2,tblSource[Period],C2,tblSource[EventType],"GoldSale",tblSource[ReleaseStatus],"APPROVED"),D2*F2*G2) -> 7363381.4 | I2: =IF(INDEX(Period_Status!$B$2:$B$8,MATCH(C2,Period_Status!$A$2:$A$8,0))="ActualClosed",Controls!G2,(Gold_Stock!D2+Gold_Stock!E2-Gold_Stock!G2)*Forecast_Drivers!K2*SUMIFS(tblFX[USD_per_unit],tblFX[Period],C2,tblFX[Currency],Forecast_Drivers!J2)) -> 7363381.4 | J2: =H2-I2 -> 0
A3: S01|2026-07 | B3: S01 | C3: 46204 | D3: =Gold_Stock!F3 -> 2587.8931 | E3: =IF(INDEX(Period_Status!$B$2:$B$8,MATCH(C3,Period_Status!$A$2:$A$8,0))="ActualClosed","USD reporting",Forecast_Drivers!J3) -> USD reporting | F3: =IF(INDEX(Period_Status!$B$2:$B$8,MATCH(C3,Period_Status!$A$2:$A$8,0))="ActualClosed",IFERROR(SUMIFS(tblSource[AmountUSD],tblSource[Site],B3,tblSource[Period],C3,tblSource[EventType],"GoldSale",tblSource[ReleaseStatus],"APPROVED")/SUMIFS(tblSource[QuantityOz],tblSource[Site],B3,tblSource[Period],C3,tblSource[EventType],"GoldSale",tblSource[ReleaseStatus],"APPROVED"),0),Forecast_Drivers!K3) -> 2941.5312 | G3: =IF(INDEX(Period_Status!$B$2:$B$8,MATCH(C3,Period_Status!$A$2:$A$8,0))="ActualClosed",1,SUMIFS(tblFX[USD_per_unit],tblFX[Period],C3,tblFX[Currency],E3)) -> 1 | H3: =SUMIFS(Source_Detail!$K$2:$K$4591,Source_Detail!$D$2:$D$4591,B3,Source_Detail!$B$2:$B$4591,C3,Source_Detail!$E$2:$E$4591,"GoldSale") -> 5208996.6 | I3: =IF(INDEX(Period_Status!$B$2:$B$8,MATCH(C3,Period_Status!$A$2:$A$8,0))="ActualClosed",Controls!G3,(Gold_Stock!D3+Gold_Stock!E3-Gold_Stock!G3)*Forecast_Drivers!K3*SUMIFS(tblFX[USD_per_unit],tblFX[Period],C3,tblFX[Currency],Forecast_Drivers!J3)) -> 7612368.4 | J3: =H3-I3 -> -2403371.8
A4: S01|2026-08 | B4: S01 | C4: 46235 | D4: =Gold_Stock!F4 -> 2920.27 | E4: =IF(INDEX(Period_Status!$B$2:$B$8,MATCH(C4,Period_Status!$A$2:$A$8,0))="ActualClosed","USD reporting",Forecast_Drivers!J4) -> USD | F4: =IF(INDEX(Period_Status!$B$2:$B$8,MATCH(C4,Period_Status!$A$2:$A$8,0))="ActualClosed",IFERROR(SUMIFS(tblSource[AmountUSD],tblSource[Site],B4,tblSource[Period],C4,tblSource[EventType],"GoldSale",tblSource[ReleaseStatus],"APPROVED")/SUMIFS(tblSource[QuantityOz],tblSource[Site],B4,tblSource[Period],C4,tblSource[EventType],"GoldSale",tblSource[ReleaseStatus],"APPROVED"),0),Forecast_Drivers!K4) -> 2980 | G4: =IF(INDEX(Period_Status!$B$2:$B$8,MATCH(C4,Period_Status!$A$2:$A$8,0))="ActualClosed",1,SUMIFS(tblFX[USD_per_unit],tblFX[Period],C4,tblFX[Currency],E4)) -> 1 | H4: =IF(INDEX(Period_Status!$B$2:$B$8,MATCH(C4,Period_Status!$A$2:$A$8,0))="ActualClosed",SUMIFS(tblSource[AmountUSD],tblSource[Site],B4,tblSource[Period],C4,tblSource[EventType],"GoldSale",tblSource[ReleaseStatus],"APPROVED"),D4*F4*G4) -> 8702404.7 | I4: =IF(INDEX(Period_Status!$B$2:$B$8,MATCH(C4,Period_Status!$A$2:$A$8,0))="ActualClosed",Controls!G4,(Gold_Stock!D4+Gold_Stock!E4-Gold_Stock!G4)*Forecast_Drivers!K4*SUMIFS(tblFX[USD_per_unit],tblFX[Period],C4,tblFX[Currency],Forecast_Drivers!J4)) -> 8702404.7 | J4: =H4-I4 -> 0
A5: S01|2026-09 | B5: S01 | C5: 46266 | D5: =Gold_Stock!F5 -> 2935.914 | E5: =IF(INDEX(Period_Status!$B$2:$B$8,MATCH(C5,Period_Status!$A$2:$A$8,0))="ActualClosed","USD reporting",Forecast_Drivers!J5) -> USD | F5: =IF(INDEX(Period_Status!$B$2:$B$8,MATCH(C5,Period_Status!$A$2:$A$8,0))="ActualClosed",IFERROR(SUMIFS(tblSource[AmountUSD],tblSource[Site],B5,tblSource[Period],C5,tblSource[EventType],"GoldSale",tblSource[ReleaseStatus],"APPROVED")/SUMIFS(tblSource[QuantityOz],tblSource[Site],B5,tblSource[Period],C5,tblSource[EventType],"GoldSale",tblSource[ReleaseStatus],"APPROVED"),0),Forecast_Drivers!K5) -> 3010 | G5: =IF(INDEX(Period_Status!$B$2:$B$8,MATCH(C5,Period_Status!$A$2:$A$8,0))="ActualClosed",1,SUMIFS(tblFX[USD_per_unit],tblFX[Period],C5,tblFX[Currency],E5)) -> 1 | H5: =IF(INDEX(Period_Status!$B$2:$B$8,MATCH(C5,Period_Status!$A$2:$A$8,0))="ActualClosed",SUMIFS(tblSource[AmountUSD],tblSource[Site],B5,tblSource[Period],C5,tblSource[EventType],"GoldSale",tblSource[ReleaseStatus],"APPROVED"),D5*F5*G5) -> 8837101 | I5: =IF(INDEX(Period_Status!$B$2:$B$8,MATCH(C5,Period_Status!$A$2:$A$8,0))="ActualClosed",Controls!G5,(Gold_Stock!D5+Gold_Stock!E5-Gold_Stock!G5)*Forecast_Drivers!K5*SUMIFS(tblFX[USD_per_unit],tblFX[Period],C5,tblFX[Currency],Forecast_Drivers!J5)) -> 8791951 | J5: =H5-I5 -> 45150
A6: S01|2026-10 | B6: S01 | C6: 46296 | D6: =Gold_Stock!F6 -> 3055.4095 | E6: =IF(INDEX(Period_Status!$B$2:$B$8,MATCH(C6,Period_Status!$A$2:$A$8,0))="ActualClosed","USD reporting",Forecast_Drivers!J6) -> USD | F6: =IF(INDEX(Period_Status!$B$2:$B$8,MATCH(C6,Period_Status!$A$2:$A$8,0))="ActualClosed",IFERROR(SUMIFS(tblSource[AmountUSD],tblSource[Site],B6,tblSource[Period],C6,tblSource[EventType],"GoldSale",tblSource[ReleaseStatus],"APPROVED")/SUMIFS(tblSource[QuantityOz],tblSource[Site],B6,tblSource[Period],C6,tblSource[EventType],"GoldSale",tblSource[ReleaseStatus],"APPROVED"),0),Forecast_Drivers!K6) -> 3040 | G6: =IF(INDEX(Period_Status!$B$2:$B$8,MATCH(C6,Period_Status!$A$2:$A$8,0))="ActualClosed",1,SUMIFS(tblFX[USD_per_unit],tblFX[Period],C6,tblFX[Currency],E6)) -> 1 | H6: =IF(INDEX(Period_Status!$B$2:$B$8,MATCH(C6,Period_Status!$A$2:$A$8,0))="ActualClosed",SUMIFS(tblSource[AmountUSD],tblSource[Site],B6,tblSource[Period],C6,tblSource[EventType],"GoldSale",tblSource[ReleaseStatus],"APPROVED"),D6*F6*G6) -> 9288444.9 | I6: =IF(INDEX(Period_Status!$B$2:$B$8,MATCH(C6,Period_Status!$A$2:$A$8,0))="ActualClosed",Controls!G6,(Gold_Stock!D6+Gold_Stock!E6-Gold_Stock!G6)*Forecast_Drivers!K6*SUMIFS(tblFX[USD_per_unit],tblFX[Period],C6,tblFX[Currency],Forecast_Drivers!J6)) -> 9288444.9 | J6: =H6-I6 -> 0
A7: S01|2026-11 | B7: S01 | C7: 46327 | D7: =Gold_Stock!F7 -> 2726.345 | E7: =IF(INDEX(Period_Status!$B$2:$B$8,MATCH(C7,Period_Status!$A$2:$A$8,0))="ActualClosed","USD reporting",Forecast_Drivers!J7) -> USD | F7: =IF(INDEX(Period_Status!$B$2:$B$8,MATCH(C7,Period_Status!$A$2:$A$8,0))="ActualClosed",IFERROR(SUMIFS(tblSource[AmountUSD],tblSource[Site],B7,tblSource[Period],C7,tblSource[EventType],"GoldSale",tblSource[ReleaseStatus],"APPROVED")/SUMIFS(tblSource[QuantityOz],tblSource[Site],B7,tblSource[Period],C7,tblSource[EventType],"GoldSale",tblSource[ReleaseStatus],"APPROVED"),0),Forecast_Drivers!K7) -> 3070 | G7: =IF(INDEX(Period_Status!$B$2:$B$8,MATCH(C7,Period_Status!$A$2:$A$8,0))="ActualClosed",1,SUMIFS(tblFX[USD_per_unit],tblFX[Period],C7,tblFX[Currency],E7)) -> 1 | H7: =IF(INDEX(Period_Status!$B$2:$B$8,MATCH(C7,Period_Status!$A$2:$A$8,0))="ActualClosed",SUMIFS(tblSource[AmountUSD],tblSource[Site],B7,tblSource[Period],C7,tblSource[EventType],"GoldSale",tblSource[ReleaseStatus],"APPROVED"),D7*F7*G7) -> 8369879 | I7: =IF(INDEX(Period_Status!$B$2:$B$8,MATCH(C7,Period_Status!$A$2:$A$8,0))="ActualClosed",Controls!G7,(Gold_Stock!D7+Gold_Stock!E7-Gold_Stock!G7)*Forecast_Drivers!K7*SUMIFS(tblFX[USD_per_unit],tblFX[Period],C7,tblFX[Currency],Forecast_Drivers!J7)) -> 8369879 | J7: =H7-I7 -> 0
A8: S01|2026-12 | B8: S01 | C8: 46357 | D8: =Gold_Stock!F8 -> 3164.7713 | E8: =IF(INDEX(Period_Status!$B$2:$B$8,MATCH(C8,Period_Status!$A$2:$A$8,0))="ActualClosed","USD reporting",Forecast_Drivers!J8) -> USD | F8: =IF(INDEX(Period_Status!$B$2:$B$8,MATCH(C8,Period_Status!$A$2:$A$8,0))="ActualClosed",IFERROR(SUMIFS(tblSource[AmountUSD],tblSource[Site],B8,tblSource[Period],C8,tblSource[EventType],"GoldSale",tblSource[ReleaseStatus],"APPROVED")/SUMIFS(tblSource[QuantityOz],tblSource[Site],B8,tblSource[Period],C8,tblSource[EventType],"GoldSale",tblSource[ReleaseStatus],"APPROVED"),0),Forecast_Drivers!K8) -> 3100 | G8: =IF(INDEX(Period_Status!$B$2:$B$8,MATCH(C8,Period_Status!$A$2:$A$8,0))="ActualClosed",1,SUMIFS(tblFX[USD_per_unit],tblFX[Period],C8,tblFX[Currency],E8)) -> 1 | H8: =IF(INDEX(Period_Status!$B$2:$B$8,MATCH(C8,Period_Status!$A$2:$A$8,0))="ActualClosed",SUMIFS(tblSource[AmountUSD],tblSource[Site],B8,tblSource[Period],C8,tblSource[EventType],"GoldSale",tblSource[ReleaseStatus],"APPROVED"),D8*F8*G8) -> 9810791 | I8: =IF(INDEX(Period_Status!$B$2:$B$8,MATCH(C8,Period_Status!$A$2:$A$8,0))="ActualClosed",Controls!G8,(Gold_Stock!D8+Gold_Stock!E8-Gold_Stock!G8)*Forecast_Drivers!K8*SUMIFS(tblFX[USD_per_unit],tblFX[Period],C8,tblFX[Currency],Forecast_Drivers!J8)) -> 9810791 | J8: =H8-I8 -> 0
A9: S02|2026-06 | B9: S02 | C9: 46174 | D9: =Gold_Stock!F9 -> 1525.0351 | E9: =IF(INDEX(Period_Status!$B$2:$B$8,MATCH(C9,Period_Status!$A$2:$A$8,0))="ActualClosed","USD reporting",Forecast_Drivers!J9) -> USD reporting | F9: =IF(INDEX(Period_Status!$B$2:$B$8,MATCH(C9,Period_Status!$A$2:$A$8,0))="ActualClosed",IFERROR(SUMIFS(tblSource[AmountUSD],tblSource[Site],B9,tblSource[Period],C9,tblSource[EventType],"GoldSale",tblSource[ReleaseStatus],"APPROVED")/SUMIFS(tblSource[QuantityOz],tblSource[Site],B9,tblSource[Period],C9,tblSource[EventType],"GoldSale",tblSource[ReleaseStatus],"APPROVED"),0),Forecast_Drivers!K9) -> 2920.1227 | G9: =IF(INDEX(Period_Status!$B$2:$B$8,MATCH(C9,Period_Status!$A$2:$A$8,0))="ActualClosed",1,SUMIFS(tblFX[USD_per_unit],tblFX[Period],C9,tblFX[Currency],E9)) -> 1 | H9: =IF(INDEX(Period_Status!$B$2:$B$8,MATCH(C9,Period_Status!$A$2:$A$8,0))="ActualClosed",SUMIFS(tblSource[AmountUSD],tblSource[Site],B9,tblSource[Period],C9,tblSource[EventType],"GoldSale",tblSource[ReleaseStatus],"APPROVED"),D9*F9*G9) -> 4453289.6 | I9: =IF(INDEX(Period_Status!$B$2:$B$8,MATCH(C9,Period_Status!$A$2:$A$8,0))="ActualClosed",Controls!G9,(Gold_Stock!D9+Gold_Stock!E9-Gold_Stock!G9)*Forecast_Drivers!K9*SUMIFS(tblFX[USD_per_unit],tblFX[Period],C9,tblFX[Currency],Forecast_Drivers!J9)) -> 4453289.6 | J9: =H9-I9 -> 0
A10: S02|2026-07 | B10: S02 | C10: 46204 | D10: =Gold_Stock!F10 -> 1572.1965 | E10: =IF(INDEX(Period_Status!$B$2:$B$8,MATCH(C10,Period_Status!$A$2:$A$8,0))="ActualClosed","USD reporting",Forecast_Drivers!J10) -> USD reporting | F10: =IF(INDEX(Period_Status!$B$2:$B$8,MATCH(C10,Period_Status!$A$2:$A$8,0))="ActualClosed",IFERROR(SUMIFS(tblSource[AmountUSD],tblSource[Site],B10,tblSource[Period],C10,tblSource[EventType],"GoldSale",tblSource[ReleaseStatus],"APPROVED")/SUMIFS(tblSource[QuantityOz],tblSource[Site],B10,tblSource[Period],C10,tblSource[EventType],"GoldSale",tblSource[ReleaseStatus],"APPROVED"),0),Forecast_Drivers!K10) -> 2952.5241 | G10: =IF(INDEX(Period_Status!$B$2:$B$8,MATCH(C10,Period_Status!$A$2:$A$8,0))="ActualClosed",1,SUMIFS(tblFX[USD_per_unit],tblFX[Period],C10,tblFX[Currency],E10)) -> 1 | H10: =IF(INDEX(Period_Status!$B$2:$B$8,MATCH(C10,Period_Status!$A$2:$A$8,0))="ActualClosed",SUMIFS(tblSource[AmountUSD],tblSource[Site],B10,tblSource[Period],C10,tblSource[EventType],"GoldSale",tblSource[ReleaseStatus],"APPROVED"),D10*F10*G10) -> 4641948 | I10: =IF(INDEX(Period_Status!$B$2:$B$8,MATCH(C10,Period_Status!$A$2:$A$8,0))="ActualClosed",Controls!G10,(Gold_Stock!D10+Gold_Stock!E10-Gold_Stock!G10)*Forecast_Drivers!K10*SUMIFS(tblFX[USD_per_unit],tblFX[Period],C10,tblFX[Currency],Forecast_Drivers!J10)) -> 4641948 | J10: =H10-I10 -> 0
A11: S02|2026-08 | B11: S02 | C11: 46235 | D11: =Gold_Stock!F11 -> 1808.0189 | E11: =IF(INDEX(Period_Status!$B$2:$B$8,MATCH(C11,Period_Status!$A$2:$A$8,0))="ActualClosed","USD reporting",Forecast_Drivers!J11) -> AUD | F11: =IF(INDEX(Period_Status!$B$2:$B$8,MATCH(C11,Period_Status!$A$2:$A$8,0))="ActualClosed",IFERROR(SUMIFS(tblSource[AmountUSD],tblSource[Site],B11,tblSource[Period],C11,tblSource[EventType],"GoldSale",tblSource[ReleaseStatus],"APPROVED")/SUMIFS(tblSource[QuantityOz],tblSource[Site],B11,tblSource[Period],C11,tblSource[EventType],"GoldSale",tblSource[ReleaseStatus],"APPROVED"),0),Forecast_Drivers!K11) -> 4584.6154 | G11: =Assumptions!D5 -> 0.658 | H11: =IF(INDEX(Period_Status!$B$2:$B$8,MATCH(C11,Period_Status!$A$2:$A$8,0))="ActualClosed",SUMIFS(tblSource[AmountUSD],tblSource[Site],B11,tblSource[Period],C11,tblSource[EventType],"GoldSale",tblSource[ReleaseStatus],"APPROVED"),D11*F11*G11) -> 5454208.8 | I11: =IF(INDEX(Period_Status!$B$2:$B$8,MATCH(C11,Period_Status!$A$2:$A$8,0))="ActualClosed",Controls!G11,(Gold_Stock!D11+Gold_Stock!E11-Gold_Stock!G11)*Forecast_Drivers!K11*SUMIFS(tblFX[USD_per_unit],tblFX[Period],C11,tblFX[Currency],Forecast_Drivers!J11)) -> 5387896.3 | J11: =H11-I11 -> 66312.57
A12: S02|2026-09 | B12: S02 | C12: 46266 | D12: =Gold_Stock!F12 -> 1848.7379 | E12: =IF(INDEX(Period_Status!$B$2:$B$8,MATCH(C12,Period_Status!$A$2:$A$8,0))="ActualClosed","USD reporting",Forecast_Drivers!J12) -> AUD | F12: =IF(INDEX(Period_Status!$B$2:$B$8,MATCH(C12,Period_Status!$A$2:$A$8,0))="ActualClosed",IFERROR(SUMIFS(tblSource[AmountUSD],tblSource[Site],B12,tblSource[Period],C12,tblSource[EventType],"GoldSale",tblSource[ReleaseStatus],"APPROVED")/SUMIFS(tblSource[QuantityOz],tblSource[Site],B12,tblSource[Period],C12,tblSource[EventType],"GoldSale",tblSource[ReleaseStatus],"APPROVED"),0),Forecast_Drivers!K12) -> 4623.6559 | G12: =IF(INDEX(Period_Status!$B$2:$B$8,MATCH(C12,Period_Status!$A$2:$A$8,0))="ActualClosed",1,SUMIFS(tblFX[USD_per_unit],tblFX[Period],C12,tblFX[Currency],E12)) -> 0.651 | H12: =IF(INDEX(Period_Status!$B$2:$B$8,MATCH(C12,Period_Status!$A$2:$A$8,0))="ActualClosed",SUMIFS(tblSource[AmountUSD],tblSource[Site],B12,tblSource[Period],C12,tblSource[EventType],"GoldSale",tblSource[ReleaseStatus],"APPROVED"),D12*F12*G12) -> 5564701 | I12: =IF(INDEX(Period_Status!$B$2:$B$8,MATCH(C12,Period_Status!$A$2:$A$8,0))="ActualClosed",Controls!G12,(Gold_Stock!D12+Gold_Stock!E12-Gold_Stock!G12)*Forecast_Drivers!K12*SUMIFS(tblFX[USD_per_unit],tblFX[Period],C12,tblFX[Currency],Forecast_Drivers!J12)) -> 5564701 | J12: =H12-I12 -> 0
